Workbook
Name ACTUAR: PHVA!$B$70:$B$74
Name HACER: PHVA!$B$36:$B$65
Name PLANEAR: PHVA!$B$2:$B$35
Name VERIFICAR: PHVA!$B$66:$B$69

Sheet GRÁFICAS
A1: ACTIVO/INACTIVO | B1: (Todas)
A3: Etiquetas de fila | B3: Cuenta de Conexión | C3: Suma de PORCENTAJE
A4: AGROINSUMOS VILLACLARA SAS | B4: 1 | C4: 2
A5: ALMA BOTANICA SAS | B5: 8 | C5: 10
A6: ANA CAMPUZANO ARBOLEDA | B6: 10 | C6: 17.5
A7: BLACKRIVER FLOWERS SAS C I | B7: 13 | C7: 14.5
A8: BORJA FLOWERS SAS | B8: 10 | C8: 5
A9: CARNES MONTECARLO | B9: 5 | C9: 5 | K9: CONEXIONES SI -NO
A10: CI FLORES MUNDO COLORES SAS | B10: 12 | C10: 17.5 | K10: AVANCES DE CONEXIONES
A11: EMTURPE LIMITADA | B11: 12 | C11: 11
A12: ESTRUCTURAS METALICAS DEL CHOCO | B12: 1 | C12: 1
A13: FOTO SCANNER | B13: 3 | C13: 4
A14: HYDRANFLOWERS S.A.S | B14: 8 | C14: 5.5
A15: INVERSIONES VALLEJUELO S.A.S. | B15: 9 | C15: 11
A16: JORGE ELIECER GOMEZ | B16: 2 | C16: 0
A17: JULIAN GALLEGO CASTRO | B17: 8 | C17: 15
A18: LACTEOS BUENA VISTA SABORES NATURALES S A | B18: 10 | C18: 18
A19: LOPETRANS SAS | B19: 13 | C19: 23
A20: MADERAS SAN RAFAEL | B20: 11 | C20: 15
A21: OLGA LÓPEZ | B21: 6 | C21: 3.5
A22: PROSOLAR S.A.S | B22: 8 | C22: 8.5
... A29: Total general | B29: 205 | C29: 259.5
A31: Etiquetas de fila | B31: Cuenta de NIVEL DE RIESGO
A32: 1 | B32: 33
A33: 2 | B33: 51
A34: 3 | B34: 66
A35: 4 | B35: 30
A36: 5 | B36: 23
A37: (en blanco)
A38: Total general | B38: 203
A40: Etiquetas de fila | B40: Cuenta de NÚMERO DE EMPLEADOS
A41: AGROINSUMOS VILLACLARA SAS | B41: 1
A42: ALMA BOTANICA SAS | B42: 8
A43: ANA CAMPUZANO ARBOLEDA | B43: 10
A44: BLACKRIVER FLOWERS SAS C I | B44: 13
A45: BORJA FLOWERS SAS | B45: 10
A46: CARNES MONTECARLO | B46: 5
A47: CI FLORES MUNDO COLORES SAS | B47: 12
A48: EMTURPE LIMITADA | B48: 12
A49: ESTRUCTURAS METALICAS DEL CHOCO | B49: 1
...

Sheet CRM ANALISTAS
A1: FECHA INICIO DEL PROGRAMA | B1: MES DE INICIO COBERTURA | C1: MESES A CORTE 30 DE MAYO | D1: Día | E1: Programa | F1: Analista | G1: Nombre | H1: Tipo de documento | I1: N.Identificación | J1: Correo electrónico1 | K1: Número de celular | L1: Nombre de la empresa | M1: NIT | N1: Conexión | O1: Hora | P1: NIVEL DE RIESGO | Q1: VALOR | R1: ASISTENCIA | S1: CICLO | T1: ESTANDAR 0312 DE 2019 | U1: PORCENTAJE AVANCE | V1: Acompañamiento 1 | W1: FECHA DE INFORME | X1: DÍAS EN EL PROGRAMA | Y1: NÚMERO DE EMPLEADOS | Z1: ACTIVO/INACTIVO
A2: 45797 | B2: MAYO | C2: 1 | D2: MARTES | E2: TU EMPRESA SEGURA | F2: LUZ | G2: ALEXIS PÉREZ GÓMEZ | H2: Cédula de Ciudadanía | I2: 1040325965 | J2: contacto@villaclara.com.co | K2: 3132973915 | L2: AGROINSUMOS VILLACLARA SAS | M2: 901250630 | N2: 45797 | O2: 11:30 a.m | P2: 1 | Q2: =IF(OR(P2=1,P2=2,P2=3),106666,IF(OR(P2=4,P2=5),213000,"")) -> 106666 | R2: SI | S2: PLANEAR | T2: 1.0.6 Diagnóstico del Sistema de Gestión de Seguridad y Salud en el Trabajo (SG-SST) 0312 DE 2019 | U2: =IFERROR(VLOOKUP(T2,PHVA!$B$2:$C$74,2,0),0) -> 2 | V2: No firmo firma de termminos y condiciones por temas de no tener contraseña y usuario,se le presenta el programa .se le realiza evaluacion inicial | W2: 45807 | X2: =ABS(A2-W2) -> 10 | Y2: =VLOOKUP(M2,Hoja3!$L$2:$X$26,13,0) -> 14 | Z2: ACTIVO
A3: 45751 | B3: ABRIL | C3: 2 | D3: VIERNES | E3: TU EMPRESA SEGURA | F3: Juan Diego | G3: MERCEDES CARVAJAL OSPINA | H3: Cédula de Ciudadanía | I3: 21481666 | J3: mercedesemprendedora2023@gmail.com | K3: 3053436587 | L3: ALMA BOTANICA SAS | M3: 901817841 | N3: 45751 | O3: 11:30a.m | P3: 4 | Q3: =IF(OR(P3=1,P3=2,P3=3),106666,IF(OR(P3=4,P3=5),213000,"")) -> 213000 | R3: SI | S3: PLANEAR | T3: 1.0.4 Acompañamiiento/Asesoría sobre SGSST | U3: =IFERROR(VLOOKUP(T3,PHVA!$B$2:$C$74,2,0),0) -> 2 | V3: el dia martes 1 de abril se llamo a la empresa para poder validar si se peude contactar ya que s ehabia intentado anteriormente y no se habia logrado Presentación del Programa: Registro Usuario y contraseña, términos y condiciones y se explica reporte de incidentes y accidentes ante la ARL | W3: 45807 | X3: =ABS(A3-W3) -> 56 | Y3: =VLOOKUP(M3,Hoja3!$L$2:$X$26,13,0) -> 2 | Z3: ACTIVO
A4: 45758 | D4: VIERNES | E4: TU EMPRESA SEGURA | F4: Juan Diego | G4: MERCEDES CARVAJAL OSPINA | H4: Cédula de Ciudadanía | I4: 21481666 | J4: mercedesemprendedora2023@gmail.com | K4: 3053436587 | L4: ALMA BOTANICA SAS | M4: 901817841 | N4: 45758 | O4: 11:30a.m | P4: 4 | Q4: =IF(OR(P4=1,P4=2,P4=3),106666,IF(OR(P4=4,P4=5),213000,"")) -> 213000 | R4: SI | S4: PLANEAR | T4: 1.0.8 Ruta de Bienestar Savanna | U4: =IFERROR(VLOOKUP(T4,PHVA!$B$2:$C$74,2,0),0) -> 0 | V4: Se presenta el programa de Savanna con la Psicóloga Lorena, La primera conexión con la empresa se tuvo el día 11 de abril se hablo sobre toda la parte psicosocial que brinda la empresa -Savanna -asesorías psicológicas -Capacitaciones y talleres Se brindo toda la información de Savanna, se mostró plataforma y se envió el Excel para diligenciar información de los empleados y crear usuario y contraseña Se dio a conocer modalidad de asesorías psicológicas y la importancia de esta en las empresas Y al finalizar se dio a conocer las múltiples capacitaciones psicosociales que podemos trabajar durante el año. | W4: 45807 | X4: =ABS(A4-W4) -> 49 | Y4: =VLOOKUP(M4,Hoja3!$L$2:$X$26,13,0) -> 2 | Z4: ACTIVO
A5: 45765 | D5: VIERNES | E5: TU EMPRESA SEGURA | F5: Juan Diego | G5: MERCEDES CARVAJAL OSPINA | H5: Cédula de Ciudadanía | I5: 21481666 | J5: mercedesemprendedora2023@gmail.com | K5: 3053436587 | L5: ALMA BOTANICA SAS | M5: 901817841 | N5: 45765 | O5: 11:30a.m | P5: 4 | Q5: =IF(OR(P5=1,P5=2,P5=3),106666,IF(OR(P5=4,P5=5),213000,"")) -> 213000 | R5: NO CONEXIÓN | S5: PLANEAR | T5: 0.1 Trabajo autónomo analista en plataforma | U5: =IFERROR(VLOOKUP(T5,PHVA!$B$2:$C$74,2,0),0) -> 0.5 | V5: DIA FESTIVO | W5: 45807 | X5: =ABS(A5-W5) -> 42 | Y5: =VLOOKUP(M5,Hoja3!$L$2:$X$26,13,0) -> 2 | Z5: ACTIVO
A6: 45786 | D6: VIERNES | E6: TU EMPRESA SEGURA | F6: Juan Diego | G6: MERCEDES CARVAJAL OSPINA | H6: Cédula de Ciudadanía | I6: 21481666 | J6: mercedesemprendedora2023@gmail.com | K6: 3053436587 | L6: ALMA BOTANICA SAS | M6: 901817841 | N6: 45786 | O6: 11:30a.m | P6: 4 | Q6: =IF(OR(P6=1,P6=2,P6=3),106666,IF(OR(P6=4,P6=5),213000,"")) -> 213000 | R6: SI | S6: PLANEAR | T6: 1.1.1. Responsable del Sistema de Gestión de Seguridad y Salud en el Trabajo SG-SST | U6: =IFERROR(VLOOKUP(T6,PHVA!$B$2:$C$74,2,0),0) -> 0.5 | V6: se inicia con la asignacion de responsable del SGSST y se continua con el procedimiento de gestion documental; se deja pendiente la realizacion de los examenes medicos ocupacionales | W6: 45807 | X6: =ABS(A6-W6) -> 21 | Y6: =VLOOKUP(M6,Hoja3!$L$2:$X$26,13,0) -> 2 | Z6: ACTIVO
A7: 45793 | D7: VIERNES | E7: TU EMPRESA SEGURA | F7: Juan Diego | G7: MERCEDES CARVAJAL OSPINA | H7: Cédula de Ciudadanía | I7: 21481666 | J7: mercedesemprendedora2023@gmail.com | K7: 3053436587 | L7: ALMA BOTANICA SAS | M7: 901817841 | N7: 45793 | O7: 11:30a.m | P7: 4 | Q7: =IF(OR(P7=1,P7=2,P7=3),106666,IF(OR(P7=4,P7=5),213000,"")) -> 213000 | R7: SI | S7: PLANEAR | T7: 1.0.3 Navegando en la plataforma y beneficios del programa | U7: =IFERROR(VLOOKUP(T7,PHVA!$B$2:$C$74,2,0),0) -> 1 | V7: se realiza registro de empleados en plataforma | W7: 45807 | X7: =ABS(A7-W7) -> 14 | Y7: =VLOOKUP(M7,Hoja3!$L$2:$X$26,13,0) -> 2 | Z7: ACTIVO
A8: 45807 | D8: VIERNES | E8: TU EMPRESA SEGURA | F8: Juan Diego | G8: MERCEDES CARVAJAL OSPINA | H8: Cédula de Ciudadanía | I8: 21481666 | J8: mercedesemprendedora2023@gmail.com | K8: 3053436587 | L8: ALMA BOTANICA SAS | M8: 901817841 | N8: 45807 | O8: 11:30a.m | P8: 4 | Q8: =IF(OR(P8=1,P8=2,P8=3),106666,IF(OR(P8=4,P8=5),213000,"")) -> 213000 | R8: SI | S8: PLANEAR | T8: 1.0.4 Acompañamiiento/Asesoría sobre SGSST | U8: =IFERROR(VLOOKUP(T8,PHVA!$B$2:$C$74,2,0),0) -> 2 | V8: se consulta sobre estado de examenes médicos, se explican los tipos segun la normativa y se asignan responsabilidades | W8: 45807 | X8: =ABS(A8-W8) -> 0 | Y8: =VLOOKUP(M8,Hoja3!$L$2:$X$26,13,0) -> 2 | Z8: ACTIVO
A9: 45814 | D9: VIERNES | E9: TU EMPRESA SEGURA | F9: Juan Diego | G9: MERCEDES CARVAJAL OSPINA | H9: Cédula de Ciudadanía | I9: 21481666 | J9: mercedesemprendedora2023@gmail.com | K9: 3053436587 | L9: ALMA BOTANICA SAS | M9: 901817841 | N9: 45814 | O9: 11:30a.m | P9: 4 | Q9: =IF(OR(P9=1,P9=2,P9=3),106666,IF(OR(P9=4,P9=5),213000,"")) -> 213000 | R9: SI | S9: PLANEAR | T9: 1.0.4 Acompañamiiento/Asesoría sobre SGSST | U9: =IFERROR(VLOOKUP(T9,PHVA!$B$2:$C$74,2,0),0) -> 2 | V9: Se realiza, acta de actividades de alto riesgo, se ingresan planillas de examenes medicos | W9: 45807 | X9: =ABS(A9-W9) -> 7 | Y9: =VLOOKUP(M9,Hoja3!$L$2:$X$26,13,0) -> 2 | Z9: ACTIVO
A10: 45793 | D10: VIERNES | E10: TU EMPRESA SEGURA | F10: Juan Diego | G10: MERCEDES CARVAJAL OSPINA | H10: Cédula de Ciudadanía | I10: 21481666 | J10: mercedesemprendedora2023@gmail.com | K10: 3053436587 | L10: ALMA BOTANICA SAS | M10: 901817841 | N10: 45793 | P10: 4 | Q10: =IF(OR(P10=1,P10=2,P10=3),106666,IF(OR(P10=4,P10=5),213000,"")) -> 213000 | R10: SI | S10: PLANEAR | T10: 1.0.4 Acompañamiiento/Asesoría sobre SGSST | U10: =IFERROR(VLOOKUP(T10,PHVA!$B$2:$C$74,2,0),0) -> 2 | V10: Se xplica la importancia de los examenes médicos, como hacer lagestion, y se empieza a registrar el personal | W10: 45807 | X10: =ABS(A10-W10) -> 14 | Y10: =VLOOKUP(M10,Hoja3!$L$2:$X$26,13,0) -> 2 | Z10: ACTIVO
A11: 45744 | B11: MARZO | C11: 3 | D11: VIERNES | E11: TU EMPRESA SEGURA | F11: Cristhian | G11: Ana Maria Campuzano Arboleda | H11: Cédula de Ciudadanía | I11: 1007445947 | J11: anam_campuzano@hotmail.com | K11: 3217213077 | L11: ANA CAMPUZANO ARBOLEDA | M11: 1007445947 | N11: 45744 | O11: 11:30a.m | P11: 2 | Q11: =IF(OR(P11=1,P11=2,P11=3),106666,IF(OR(P11=4,P11=5),213000,"")) -> 106666 | R11: SI | S11: PLANEAR | T11: 1.0.0 Bienvenida | U11: =IFERROR(VLOOKUP(T11,PHVA!$B$2:$C$74,2,0),0) -> 1 | V11: Bienvenida al programa, se le explica detalladamente en que consiste y la duración estimada, se Indica cómo firmar los términos y condiciones, se agenda la reunión periódica, semanal, los viernes de 11:30 a 12:15pm | W11: 45807 | X11: =ABS(A11-W11) -> 63 | Y11: =VLOOKUP(M11,Hoja3!$L$2:$X$26,13,0) -> 2 | Z11: ACTIVO
A12: 45751 | D12: VIERNES | E12: TU EMPRESA SEGURA | F12: Cristhian | G12: Ana Maria Campuzano Arboleda | H12: Cédula de Ciudadanía | I12: 1007445947 | J12: anam_campuzano@hotmail.com | K12: 3217213077 | L12: ANA CAMPUZANO ARBOLEDA | M12: 1007445947 | N12: 45751 | O12: 11:30a.m | P12: 2 | Q12: =IF(OR(P12=1,P12=2,P12=3),106666,IF(OR(P12=4,P12=5),213000,"")) -> 106666 | R12: SI | S12: PLANEAR | T12: 1.0.5 Diagnóstico de Madurez | U12: =IFERROR(VLOOKUP(T12,PHVA!$B$2:$C$74,2,0),0) -> 3 | V12: Se realiza el diagnostico de madurez | W12: 45807 | Y12: =VLOOKUP(M12,Hoja3!$L$2:$X$26,13,0) -> 2 | Z12: ACTIVO
A13: 45758 | D13: VIERNES | E13: TU EMPRESA SEGURA | F13: Cristhian | G13: Ana Maria Campuzano Arboleda | H13: Cédula de Ciudadanía | I13: 1007445947 | J13: anam_campuzano@hotmail.com | K13: 3217213077 | L13: ANA CAMPUZANO ARBOLEDA | M13: 1007445947 | N13: 45758 | O13: 11:30a.m | P13: 2 | Q13: =IF(OR(P13=1,P13=2,P13=3),106666,IF(OR(P13=4,P13=5),213000,"")) -> 106666 | R13: SI | S13: PLANEAR | T13: 1.0.6 Diagnóstico del Sistema de Gestión de Seguridad y Salud en el Trabajo (SG-SST) 0312 DE 2019 | U13: =IFERROR(VLOOKUP(T13,PHVA!$B$2:$C$74,2,0),0) -> 2 | V13: Se realiza la evaluacion inicial del sistema de gestion, se dan recomendaciones iniciales | W13: 45807 | X13: =ABS(A13-W13) -> 49 | Y13: =VLOOKUP(M13,Hoja3!$L$2:$X$26,13,0) -> 2 | Z13: ACTIVO
A14: 45765 | D14: VIERNES | E14: TU EMPRESA SEGURA | F14: LUZ | G14: Ana Maria Campuzano Arboleda | H14: Cédula de Ciudadanía | I14: 1007445947 | J14: anam_campuzano@hotmail.com | K14: 3217213077 | L14: ANA CAMPUZANO ARBOLEDA | M14: 1007445947 | N14: 45765 | O14: 11:30a.m | P14: 2 | Q14: =IF(OR(P14=1,P14=2,P14=3),106666,IF(OR(P14=4,P14=5),213000,"")) -> 106666 | R14: NO | S14: PLANEAR | T14: 1.0.4 Acompañamiiento/Asesoría sobre SGSST | U14: =IFERROR(VLOOKUP(T14,PHVA!$B$2:$C$74,2,0),0) -> 2 | V14: El 24 de abril del 2025 me transfieren a Doña ana ,Era del analista Cristian. | W14: 45807 | X14: =ABS(A14-W14) -> 42 | Y14: =VLOOKUP(M14,Hoja3!$L$2:$X$26,13,0) -> 2 | Z14: ACTIVO
A15: 45771 | D15: JUEVES | E15: TU EMPRESA SEGURA | F15: LUZ | G15: Ana Maria Campuzano Arboleda | H15: Cédula de Ciudadanía | I15: 1007445947 | J15: anam_campuzano@hotmail.com | K15: 3217213077 | L15: ANA CAMPUZANO ARBOLEDA | M15: 1007445947 | N15: 45772 | O15: 11:30a.m | P15: 2 | Q15: =IF(OR(P15=1,P15=2,P15=3),106666,IF(OR(P15=4,P15=5),213000,"")) -> 106666 | R15: SI | S15: PLANEAR | T15: 1.0.1 Firma de Términos y Condiciones | U15: =IFERROR(VLOOKUP(T15,PHVA!$B$2:$C$74,2,0),0) -> 1 | V15: La señora ana refiere que con en analista Cristian se realizo,Firma de documento de terminos y condiciones,cuenta con contraseña y usuario,se le realizo el diagnostico inicial.Hoy 24 de abril,se le informanuevamente del programa,se actualiza informacion de empresa,se le solicita documentos rut ,camara y comercio etc,se le informa del procedimiento del archivo documental y su importancia para continuar diligenciando documentos y se le explica el numerar 1.1.4. | W15: 45807 | X15: =ABS(A15-W15) -> 36 | Y15: =VLOOKUP(M15,Hoja3!$L$2:$X$26,13,0) -> 2 | Z15: ACTIVO
A16: 45724 | D16: JUEVES | E16: TU EMPRESA SEGURA | F16: LUZ | G16: Ana Maria Campuzano Arboleda | H16: Cédula de Ciudadanía | I16: 1007445947 | J16: anam_campuzano@hotmail.com | K16: 3217213077 | L16: ANA CAMPUZANO ARBOLEDA | M16: 1007445947 | N16: 45785 | O16: 11:30a.m | P16: 2 | Q16: =IF(OR(P16=1,P16=2,P16=3),106666,IF(OR(P16=4,P16=5),213000,"")) -> 106666 | R16: SI | S16: PLANEAR | T16: 1.1.1. Responsable del Sistema de Gestión de Seguridad y Salud en el Trabajo SG-SST | U16: =IFERROR(VLOOKUP(T16,PHVA!$B$2:$C$74,2,0),0) -> 0.5 | V16: se realiza archivo documental,se revisa numeral 1.1.4,tarea subir el perfilsociodemogradico,se realiza diligenciamiento del responsable sst. | W16: 45807 | X16: =ABS(A16-W16) -> 83 | Y16: =VLOOKUP(M16,Hoja3!$L$2:$X$26,13,0) -> 2 | Z16: ACTIVO
A17: 45731 | D17: JUEVES | E17: TU EMPRESA SEGURA | F17: LUZ | G17: Ana Maria Campuzano Arboleda | H17: Cédula de Ciudadanía | I17: 1007445947 | J17: anam_campuzano@hotmail.com | K17: 3217213077 | L17: ANA CAMPUZANO ARBOLEDA | M17: 1007445947 | N17: 45792 | O17: 11:30a.m | P17: 2 | Q17: =IF(OR(P17=1,P17=2,P17=3),106666,IF(OR(P17=4,P17=5),213000,"")) -> 106666 | R17: NO | S17: PLANEAR | T17: 1.0.4 Acompañamiiento/Asesoría sobre SGSST | U17: =IFERROR(VLOOKUP(T17,PHVA!$B$2:$C$74,2,0),0) -> 2 | V17: Envia correo de inconveniente en conexion,se deja tareas por correo para proximo encuentro. | W17: 45807 | X17: =ABS(A17-W17) -> 76 | Y17: =VLOOKUP(M17,Hoja3!$L$2:$X$26,13,0) -> 2 | Z17: ACTIVO
A18: 45738 | D18: JUEVES | E18: TU EMPRESA SEGURA | F18: LUZ | G18: Ana Maria Campuzano Arboleda | H18: Cédula de Ciudadanía | I18: 1007445947 | J18: anam_campuzano@hotmail.com | K18: 3217213077 | L18: ANA CAMPUZANO ARBOLEDA | M18: 1007445947 | N18: 45799 | O18: 10:35a.m | P18: 2 | Q18: =IF(OR(P18=1,P18=2,P18=3),106666,IF(OR(P18=4,P18=5),213000,"")) -> 106666 | R18: SI | S18: PLANEAR | T18: 1.0.4 Acompañamiiento/Asesoría sobre SGSST | U18: =IFERROR(VLOOKUP(T18,PHVA!$B$2:$C$74,2,0),0) -> 2 | V18: Se verifica numerales del planear en archivo documental,se explica el tema de archivo documental del hacer y para la proxima reunion se realizara el tema de plan anual de trabajo. | W18: 45807 | X18: =ABS(A18-W18) -> 69 | Y18: =VLOOKUP(M18,Hoja3!$L$2:$X$26,13,0) -> 2 | Z18: ACTIVO
A19: 45745 | D19: JUEVES | E19: TU EMPRESA SEGURA | F19: LUZ | G19: Ana Maria Campuzano Arboleda | H19: Cédula de Ciudadanía | I19: 1007445947 | J19: anam_campuzano@hotmail.com | K19: 3217213077 | L19: ANA CAMPUZANO ARBOLEDA | M19: 1007445947 | N19: 45806 | O19: 10:35a.m | P19: 2 | Q19: =IF(OR(P19=1,P19=2,P19=3),106666,IF(OR(P19=4,P19=5),213000,"")) -> 106666 | R19: NO | S19: PLANEAR | T19: 1.0.4 Acompañamiiento/Asesoría sobre SGSST | U19: =IFERROR(VLOOKUP(T19,PHVA!$B$2:$C$74,2,0),0) -> 2 | V19: Envia correo de inconveniente en conexion,por temas de cita medica que se cruzaba con la conexion.solicita reprogramar para otro dia o enviarle tareaspor correo. | W19: 45807 | X19: =ABS(A19-W19) -> 62 | Y19: =VLOOKUP(M19,Hoja3!$L$2:$X$26,13,0) -> 2 | Z19: ACTIVO
A20: 45813 | D20: JUEVES | E20: TU EMPRESA SEGURA | F20: LUZ | G20: Ana Maria Campuzano Arboleda | H20: Cédula de Ciudadanía | I20: 1007445947 | J20: anam_campuzano@hotmail.com | K20: 3217213077 | L20: ANA CAMPUZANO ARBOLEDA | M20: 1007445947 | N20: 45813 | O20: 10:35a.m | P20: 2 | Q20: =IF(OR(P20=1,P20=2,P20=3),106666,IF(OR(P20=4,P20=5),213000,"")) -> 106666 | R20: SI | S20: PLANEAR | T20: 2.5.1 Archivo o retención documental del Sistema de Gestión en Seguridad y Salud en el Trabajo SG-SST | U20: =IFERROR(VLOOKUP(T20,PHVA!$B$2:$C$74,2,0),0) -> 2 | V20: LA señora ana refiere que esta interesada en continuar con lña plataforma,solo que tiene un nuevo trabajo y no le dara tiempo para conectarse,enviara correo para reprogramar tiempos o espacio de conexion ,por este motivo solo se realiza numeral 2.5.1 ,se verifica 1.1.4 ,se realiza verificacion del 3.1.1.1.,depende de la solucion al correo que envie doña ana se realizara cronograma teniendo encuenta que es solo ella y un trabajador. | W20: 45807 | X20: =ABS(A20-W20) -> 6 | Y20: =VLOOKUP(M20,Hoja3!$L$2:$X$26,13,0) -> 2 | Z20: ACTIVO
A21: 45751 | B21: ABRIL | C21: 2 | D21: VIERNES | E21: TU EMPRESA SEGURA | F21: Juan Diego | G21: MELISSA MARIA ROMAN BURITICA | H21: Cédula de Ciudadanía | I21: 1040039119 | J21: gestionhumana@blackriverflowers.com | K21: 3173882936 | L21: BLACKRIVER FLOWERS SAS C I | M21: 900841005 | N21: 45751 | O21: 10:40a. m. | P21: 3 | Q21: =IF(OR(P21=1,P21=2,P21=3),106666,IF(OR(P21=4,P21=5),213000,"")) -> 106666 | R21: SI | S21: PLANEAR | T21: 1.0.1 Firma de Términos y Condiciones | U21: =IFERROR(VLOOKUP(T21,PHVA!$B$2:$C$74,2,0),0) -> 1 | V21: el dia viernes 21 de marzo se llamo a la empresa para validar la llegada del correo electronico con el usuario y la contraseña a lo cual indicaron que si les llego y que no han tenido ningun inconveniente | W21: 45807 | X21: =ABS(A21-W21) -> 56 | Y21: =VLOOKUP(M21,Hoja3!$L$2:$X$26,13,0) -> 55 | Z21: ACTIVO
A22: 45758 | D22: VIERNES | E22: TU EMPRESA SEGURA | F22: Juan Diego | G22: MELISSA MARIA ROMAN BURITICA | H22: Cédula de Ciudadanía | I22: 1040039119 | J22: gestionhumana@blackriverflowers.com | K22: 3173882936 | L22: BLACKRIVER FLOWERS SAS C I | M22: 900841005 | N22: 45758 | O22: 10:40a. m. | P22: 3 | Q22: =IF(OR(P22=1,P22=2,P22=3),106666,IF(OR(P22=4,P22=5),213000,"")) -> 106666 | R22: NO | S22: PLANEAR | T22: 0. No participación de empresa | V22: Se actualiza plantilla de evaluacion inicial para la empresa, y seempieza con la codificacion , y procedimiento de listado maestro de documentos | W22: 45807 | X22: =ABS(A22-W22) -> 49 | Y22: =VLOOKUP(M22,Hoja3!$L$2:$X$26,13,0) -> 55 | Z22: ACTIVO
A23: 45765 | D23: VIERNES | E23: TU EMPRESA SEGURA | F23: Juan Diego | G23: MELISSA MARIA ROMAN BURITICA | H23: Cédula de Ciudadanía | I23: 1040039119 | J23: gestionhumana@blackriverflowers.com | K23: 3173882936 | L23: BLACKRIVER FLOWERS SAS C I | M23: 900841005 | N23: 45765 | O23: 10:40a. m. | P23: 3 | Q23: =IF(OR(P23=1,P23=2,P23=3),106666,IF(OR(P23=4,P23=5),213000,"")) -> 106666 | R23: NO | S23: PLANEAR | T23: 0. No participación de empresa | U23: =IFERROR(VLOOKUP(T23,PHVA!$B$2:$C$74,2,0),0) -> 0 | V23: se continua con la codificacion de documentos | W23: 45807 | X23: =ABS(A23-W23) -> 42 | Y23: =VLOOKUP(M23,Hoja3!$L$2:$X$26,13,0) -> 55 | Z23: ACTIVO
A24: 45779 | D24: VIERNES | E24: TU EMPRESA SEGURA | F24: Juan Diego | G24: MELISSA MARIA ROMAN BURITICA | H24: Cédula de Ciudadanía | I24: 1040039119 | J24: gestionhumana@blackriverflowers.com | K24: 3173882936 | L24: BLACKRIVER FLOWERS SAS C I | M24: 900841005 | N24: 45779 | O24: 10:40a. m. | P24: 3 | Q24: =IF(OR(P24=1,P24=2,P24=3),106666,IF(OR(P24=4,P24=5),213000,"")) -> 106666 | R24: NO | S24: PLANEAR | T24: 0. No participación de empresa | U24: =IFERROR(VLOOKUP(T24,PHVA!$B$2:$C$74,2,0),0) -> 0 | V24: no se conecta, se realizan las llamadas por wassap y telefonicas, y no se recibe respuesta, se gestiona documento de asignaion de responsable | W24: 45807 | X24: =ABS(A24-W24) -> 28 | Y24: =VLOOKUP(M24,Hoja3!$L$2:$X$26,13,0) -> 55 | Z24: ACTIVO
A25: 45786 | D25: VIERNES | E25: TU EMPRESA SEGURA | F25: Juan Diego | G25: MELISSA MARIA ROMAN BURITICA | H25: Cédula de Ciudadanía | I25: 1040039119 | J25: gestionhumana@blackriverflowers.com | K25: 3173882936 | L25: BLACKRIVER FLOWERS SAS C I | M25: 900841005 | N25: 45786 | O25: 10:40a. m. | P25: 3 | Q25: =IF(OR(P25=1,P25=2,P25=3),106666,IF(OR(P25=4,P25=5),213000,"")) -> 106666 | R25: NO | S25: PLANEAR | T25: 0. No participación de empresa | U25: =IFERROR(VLOOKUP(T25,PHVA!$B$2:$C$74,2,0),0) -> 0 | V25: no se conecta, escribo via whatsap, y me responden que no habia recibido la invitacion y por ende no estaba agendada para atenderme, verifico con la compañera Paula, y verificamos que la invitacion fue enviada al correo asignado por el cliente | W25: 45807 | X25: =ABS(A25-W25) -> 21 | Y25: =VLOOKUP(M25,Hoja3!$L$2:$X$26,13,0) -> 55 | Z25: ACTIVO
A26: 45793 | D26: VIERNES | E26: TU EMPRESA SEGURA | F26: LUZ | G26: MELISSA MARIA ROMAN BURITICA | H26: Cédula de Ciudadanía | I26: 1040039119 | J26: gestionhumana@blackriverflowers.com | K26: 3173882936 | L26: BLACKRIVER FLOWERS SAS C I | M26: 900841005 | N26: 45792 | O26: 8:05a. m. | P26: 3 | Q26: =IF(OR(P26=1,P26=2,P26=3),106666,IF(OR(P26=4,P26=5),213000,"")) -> 106666 | R26: SI | S26: PLANEAR | T26: 1.1.4 Afiliación al Sistema General de Riesgos Laborales | U26: =IFERROR(VLOOKUP(T26,PHVA!$B$2:$C$74,2,0),0) -> 0.5 | V26: Se realiza la conexion a las 8:41am no le fue posible conectarse antes,se le verifica firma de terminos y condiciones,la señora melissa actualizo documentos de la empresa en la plataforma,adicional de le indica como se realiza el numeral 1.1.4 y el 2.5.1 ,subira el perfil sociodemografico y se le endica que para realizar capacitaciones debemos realizar el diagnostico inicial el 22 de mayo y ahi ingresamos a realizar cronograma. | W26: 45807 | X26: =ABS(A26-W26) -> 14 | Y26: =VLOOKUP(M26,Hoja3!$L$2:$X$26,13,0) -> 55 | Z26: ACTIVO
A27: 45800 | D27: VIERNES | E27: TU EMPRESA SEGURA | F27: LUZ | G27: MELISSA MARIA ROMAN BURITICA | H27: Cédula de Ciudadanía | I27: 1040039119 | J27: gestionhumana@blackriverflowers.com | K27: 3173882936 | L27: BLACKRIVER FLOWERS SAS C I | M27: 900841005 | N27: 45799 | O27: 8:05a. m. | P27: 3 | Q27: =IF(OR(P27=1,P27=2,P27=3),106666,IF(OR(P27=4,P27=5),213000,"")) -> 106666 | R27: SI | S27: PLANEAR | T27: 1.0.6 Diagnóstico del Sistema de Gestión de Seguridad y Salud en el Trabajo (SG-SST) 0312 DE 2019 | U27: =IFERROR(VLOOKUP(T27,PHVA!$B$2:$C$74,2,0),0) -> 2 | V27: Se realiza la evaluacion inicial del diagnostico sst,se le solicita documentos para actualizacion de datos e empresa. | W27: 45807 | X27: =ABS(A27-W27) -> 7 | Y27: =VLOOKUP(M27,Hoja3!$L$2:$X$26,13,0) -> 55 | Z27: ACTIVO
A28: 45803 | D28: VIERNES | E28: TU EMPRESA SEGURA | F28: LUZ | G28: MELISSA MARIA ROMAN BURITICA | H28: Cédula de Ciudadanía | I28: 1040039119 | J28: gestionhumana@blackriverflowers.com | K28: 3173882936 | L28: BLACKRIVER FLOWERS SAS C I | M28: 900841005 | N28: 45803 | O28: 8:05a. m. | P28: 3 | Q28: =IF(OR(P28=1,P28=2,P28=3),106666,IF(OR(P28=4,P28=5),213000,"")) -> 106666 | R28: NO | S28: PLANEAR | T28: 1.0.9 Savanna Ruta de Bienestar | U28: =IFERROR(VLOOKUP(T28,PHVA!$B$2:$C$74,2,0),0) -> 4 | V28: Por temas de energia en sistegra, no fue posible la conexiony reprogramar tampoco por agenda copada. | W28: 45807 | X28: =ABS(A28-W28) -> 4 | Y28: =VLOOKUP(M28,Hoja3!$L$2:$X$26,13,0) -> 55 | Z28: ACTIVO
A29: 45807 | D29: VIERNES | E29: TU EMPRESA SEGURA | F29: LUZ | G29: MELISSA MARIA ROMAN BURITICA | H29: Cédula de Ciudadanía | I29: 1040039119 | J29: gestionhumana@blackriverflowers.com | K29: 3173882936 | L29: BLACKRIVER FLOWERS SAS C I | M29: 900841005 | N29: 45806 | O29: 8:05a. m. | P29: 3 | Q29: =IF(OR(P29=1,P29=2,P29=3),106666,IF(OR(P29=4,P29=5),213000,"")) -> 106666 | R29: NO | S29: PLANEAR | T29: 0. No participación de empresa | U29: =IFERROR(VLOOKUP(T29,PHVA!$B$2:$C$74,2,0),0) -> 0 | V29: Por temas de energia en sistegra, no fue posible la conexiony reprogramar tampoco por agenda copada. | W29: 45807 | X29: =ABS(A29-W29) -> 0 | Y29: =VLOOKUP(M29,Hoja3!$L$2:$X$26,13,0) -> 55 | Z29: ACTIVO
A30: 45814 | D30: VIERNES | E30: TU EMPRESA SEGURA | F30: LUZ | G30: MELISSA MARIA ROMAN BURITICA | H30: Cédula de Ciudadanía | I30: 1040039119 | J30: gestionhumana@blackriverflowers.com | K30: 3173882936 | L30: BLACKRIVER FLOWERS SAS C I | M30: 900841005 | N30: 45813 | O30: 8:05a. m. | P30: 3 | Q30: =IF(OR(P30=1,P30=2,P30=3),106666,IF(OR(P30=4,P30=5),213000,"")) -> 106666 | R30: SI | S30: PLANEAR | T30: 1.2.1 Programa Capacitación promoción y prevención PYP | U30: =IFERROR(VLOOKUP(T30,PHVA!$B$2:$C$74,2,0),0) -> 2 | V30: se visualisa terminos y condiciones firmada y compartida por correo,se le compartira cronograma de capacitaciones y cronograma anual de cumplimiento 0312,se verificara la contraseña y usuario para plataforma de capacitacion,no tiene datos para ingresar y solicita modificacion en representante legal porque no es ella ,melisa es de gestion humana. | W30: 45807 | X30: =ABS(A30-W30) -> 7 | Y30: =VLOOKUP(M30,Hoja3!$L$2:$X$26,13,0) -> 55 | Z30: ACTIVO
A31: 45786 | D31: VIERNES | E31: TU EMPRESA SEGURA | F31: LUZ | G31: MELISSA MARIA ROMAN BURITICA | H31: Cédula de Ciudadanía | I31: 1040039119 | J31: gestionhumana@blackriverflowers.com | K31: 3173882936 | L31: BLACKRIVER FLOWERS SAS C I | M31: 900841005 | N31: 45786 | O31: 10:40a. m. | P31: 3 | Q31: =IF(OR(P31=1,P31=2,P31=3),106666,IF(OR(P31=4,P31=5),213000,"")) -> 106666 | R31: SI | S31: PLANEAR | T31: 1.0.2 Socialización SGSST | U31: =IFERROR(VLOOKUP(T31,PHVA!$B$2:$C$74,2,0),0) -> 2 | V31: estando conectado a la hora en punto, dicen que no asistira, ya que el 12 de mayo se reuniran con Laura DIaz | W31: 45807 | X31: =ABS(A31-W31) -> 21 | Y31: =VLOOKUP(M31,Hoja3!$L$2:$X$26,13,0) -> 55 | Z31: ACTIVO
A32: 45789 | D32: LUNES | E32: TU EMPRESA SEGURA | F32: LUZ | G32: MELISSA MARIA ROMAN BURITICA | H32: Cédula de Ciudadanía | I32: 1040039119 | J32: gestionhumana@blackriverflowers.com | K32: 3173882936 | L32: BLACKRIVER FLOWERS SAS C I | M32: 900841005 | N32: 45789 | P32: 3 | Q32: =IF(OR(P32=1,P32=2,P32=3),106666,IF(OR(P32=4,P32=5),213000,"")) -> 106666 | R32: SI | S32: PLANEAR | T32: 1.0.3 Navegando en la plataforma y beneficios del programa | U32: =IFERROR(VLOOKUP(T32,PHVA!$B$2:$C$74,2,0),0) -> 1 | V32: Se muestran los beneficios del programa y se rrealiza cambio de analista con nuevo horario para facilitar al cliente las conexiones. | W32: 45789 | X32: =ABS(A32-W32) -> 0 | Y32: =VLOOKUP(M32,Hoja3!$L$2:$X$26,13,0) -> 55 | Z32: ACTIVO
A33: 45793 | D33: VIERNES | E33: TU EMPRESA SEGURA | F33: Juan Diego | G33: MELISSA MARIA ROMAN BURITICA | H33: Cédula de Ciudadanía | I33: 1040039119 | J33: gestionhumana@blackriverflowers.com | K33: 3173882936 | L33: BLACKRIVER FLOWERS SAS C I | M33: 900841005 | N33: 45786 | O33: 10:40a. m. | P33: 3 | Q33: =IF(OR(P33=1,P33=2,P33=3),106666,IF(OR(P33=4,P33=5),213000,"")) -> 106666 | R33: SI | S33: PLANEAR | T33: 1.0.2 Socialización SGSST | U33: =IFERROR(VLOOKUP(T33,PHVA!$B$2:$C$74,2,0),0) -> 2 | V33: menciona qe realiza cambio de horario autorizado por Laura Diaz | W33: 45807 | X33: =ABS(A33-W33) -> 14 | Y33: =VLOOKUP(M33,Hoja3!$L$2:$X$26,13,0) -> 55 | Z33: ACTIVO
A34: 45751 | B34: ABRIL | C34: 2 | D34: VIERNES | E34: TU EMPRESA SEGURA | F34: Juan Diego | G34: CLAUDIA PATRICIA MOLINA SANTOS | H34: Cédula de Ciudadanía | I34: 1070989191 | J34: clau300625@hotmail.es | K34: 3132973915 | L34: BORJA FLOWERS SAS | M34: 901546567 | N34: 45751 | O34: 3:55p. m. | P34: 3 | Q34: =IF(OR(P34=1,P34=2,P34=3),106666,IF(OR(P34=4,P34=5),213000,"")) -> 106666 | R34: SI | S34: PLANEAR | T34: 1.0.0 Bienvenida | U34: =IFERROR(VLOOKUP(T34,PHVA!$B$2:$C$74,2,0),0) -> 1 | V34: el dia viernes 21 de marzo se llamo a la empresa para validar la llegada del correo electronico con el usuario y la contraseña a lo cual indicaron que si les llego y que no han tenido ningun inconveniente | W34: 45807 | X34: =ABS(A34-W34) -> 56 | Y34: =VLOOKUP(M34,Hoja3!$L$2:$X$26,13,0) -> 30 | Z34: ACTIVO
A35: 45758 | D35: VIERNES | E35: TU EMPRESA SEGURA | F35: Juan Diego | G35: CLAUDIA PATRICIA MOLINA SANTOS | H35: Cédula de Ciudadanía | I35: 1070989191 | J35: clau300625@hotmail.es | K35: 3132973915 | L35: BORJA FLOWERS SAS | M35: 901546567 | N35: 45758 | O35: 3:55p. m. | P35: 3 | Q35: =IF(OR(P35=1,P35=2,P35=3),106666,IF(OR(P35=4,P35=5),213000,"")) -> 106666 | R35: SI | S35: PLANEAR | T35: 0. No participación de empresa | U35: =IFERROR(VLOOKUP(T35,PHVA!$B$2:$C$74,2,0),0) -> 0 | V35: Se reagenda espacio por calamidad de analista, se reprograma para el día 12 de abril | W35: 45807 | X35: =ABS(A35-W35) -> 49 | Y35: =VLOOKUP(M35,Hoja3!$L$2:$X$26,13,0) -> 30 | Z35: ACTIVO
A36: 45765 | D36: VIERNES | E36: TU EMPRESA SEGURA | F36: Juan Diego | G36: CLAUDIA PATRICIA MOLINA SANTOS | H36: Cédula de Ciudadanía | I36: 1070989191 | J36: clau300625@hotmail.es | K36: 3132973915 | L36: BORJA FLOWERS SAS | M36: 901546567 | N36: 45765 | O36: 3:55p. m. | P36: 3 | Q36: =IF(OR(P36=1,P36=2,P36=3),106666,IF(OR(P36=4,P36=5),213000,"")) -> 106666 | R36: CONEXIÓN AUTÓNOMA DE ANALISTA | S36: PLANEAR | T36: 0.1 Trabajo autónomo analista en plataforma | U36: =IFERROR(VLOOKUP(T36,PHVA!$B$2:$C$74,2,0),0) -> 0.5 | V36: Se adelanta documento de asignacion del responsable | W36: 45807 | X36: =ABS(A36-W36) -> 42 | Y36: =VLOOKUP(M36,Hoja3!$L$2:$X$26,13,0) -> 30 | Z36: ACTIVO
A37: 45786 | D37: VIERNES | E37: TU EMPRESA SEGURA | F37: Juan Diego | G37: CLAUDIA PATRICIA MOLINA SANTOS | H37: Cédula de Ciudadanía | I37: 1070989191 | J37: clau300625@hotmail.es | K37: 3132973915 | L37: BORJA FLOWERS SAS | M37: 901546567 | N37: 45786 | O37: 3:55p. m. | P37: 3 | Q37: =IF(OR(P37=1,P37=2,P37=3),106666,IF(OR(P37=4,P37=5),213000,"")) -> 106666 | R37: CONEXIÓN AUTÓNOMA DE ANALISTA | S37: PLANEAR | T37: 0.1 Trabajo autónomo analista en plataforma | U37: =IFERROR(VLOOKUP(T37,PHVA!$B$2:$C$74,2,0),0) -> 0.5 | V37: siendo la hora de conexion el usuario no se presenta, llamo via wassap y telefonicamente, y no recibo respuesta, se envia correo de citacion, se verifica el link y es el dado por el usuario, SE REALIZA FORMATO DE EVALUACION INICIAL, PARA CONTINUAR CON LOS CICLOS DEL P.HV.A | W37: 45807 | X37: =ABS(A37-W37) -> 21 | Y37: =VLOOKUP(M37,Hoja3!$L$2:$X$26,13,0) -> 30 | Z37: ACTIVO
A38: 45793 | D38: VIERNES | E38: TU EMPRESA SEGURA | F38: Juan Diego | G38: CLAUDIA PATRICIA MOLINA SANTOS | H38: Cédula de Ciudadanía | I38: 1070989191 | J38: clau300625@hotmail.es | K38: 3132973915 | L38: BORJA FLOWERS SAS | M38: 901546567 | N38: 45793 | O38: 3:55p. m. | P38: 3 | Q38: =IF(OR(P38=1,P38=2,P38=3),106666,IF(OR(P38=4,P38=5),213000,"")) -> 106666 | R38: SI | S38: PLANEAR | T38: 1.0.3 Navegando en la plataforma y beneficios del programa | U38: =IFERROR(VLOOKUP(T38,PHVA!$B$2:$C$74,2,0),0) -> 1 | V38: se explica programa y se da induccion de la plataforma | W38: 45807 | X38: =ABS(A38-W38) -> 14 | Y38: =VLOOKUP(M38,Hoja3!$L$2:$X$26,13,0) -> 30 | Z38: ACTIVO
A39: 45800 | D39: VIERNES | E39: TU EMPRESA SEGURA | F39: Juan Diego | G39: CLAUDIA PATRICIA MOLINA SANTOS | H39: Cédula de Ciudadanía | I39: 1070989191 | J39: clau300625@hotmail.es | K39: 3132973915 | L39: BORJA FLOWERS SAS | M39: 901546567 | N39: 45797 | O39: 3:55p. m. | P39: 3 | Q39: =IF(OR(P39=1,P39=2,P39=3),106666,IF(OR(P39=4,P39=5),213000,"")) -> 106666 | R39: CONEXIÓN AUTÓNOMA DE ANALISTA | S39: PLANEAR | T39: 0.1 Trabajo autónomo analista en plataforma | U39: =IFERROR(VLOOKUP(T39,PHVA!$B$2:$C$74,2,0),0) -> 0.5 | V39: en la hora indicada se contacta a la persona enlace, me indica que no sera posible reunirse hoy porque esta en obra. | W39: 45807 | X39: =ABS(A39-W39) -> 7 | Y39: =VLOOKUP(M39,Hoja3!$L$2:$X$26,13,0) -> 30 | Z39: ACTIVO
A40: 45797 | D40: MARTES | E40: TU EMPRESA SEGURA | F40: LUZ | G40: CLAUDIA PATRICIA MOLINA SANTOS | H40: Cédula de Ciudadanía | I40: 1070989191 | J40: clau300625@hotmail.es | K40: 3132973915 | L40: BORJA FLOWERS SAS | M40: 901546567 | N40: 45797 | O40: 3:55p. m. | P40: 3 | Q40: =IF(OR(P40=1,P40=2,P40=3),106666,IF(OR(P40=4,P40=5),213000,"")) -> 106666 | R40: NO | S40: PLANEAR | T40: 0. No conexión | U40: =IFERROR(VLOOKUP(T40,PHVA!$B$2:$C$74,2,0),0) -> 0 | V40: No se realizo la conexion por temas de coordinacion con correo . | W40: 45807 | X40: =ABS(A40-W40) -> 10 | Y40: =VLOOKUP(M40,Hoja3!$L$2:$X$26,13,0) -> 30 | Z40: ACTIVO
...

Sheet Hoja3
A1: FECHA INICIO DEL PROGRAMA | B1: MES DE INICIO COBERTURA | C1: Día | D1: Programa | E1: Analista | F1: Nombre | G1: Tipo de documento | H1: N.Identificación | I1: Correo electrónico1 | J1: Número de celular | K1: Nombre de la empresa | L1: NIT | M1: Conexión | N1: Hora | O1: HUBO CONEXIÓN | P1: NIVEL DE RIESGO | Q1: VALOR | R1: CICLO | S1: ESTANDAR 0312 DE 2019 | T1: PORCENTAJE | U1: Acompañamiento 1 | V1: FECHA DE INFORME | W1: DÍAS EN EL PROGRAMA | X1: NÚMERO DE EMPLEADOS | Y1: ACTIVO/INACTIVO
A2: 45797 | C2: MARTES | D2: TU EMPRESA SEGURA | E2: LUZ | F2: ALEXIS PÉREZ GÓMEZ | G2: Cédula de Ciudadanía | H2: 1040325965 | I2: contacto@villaclara.com.co | J2: 3132973915 | K2: AGROINSUMOS VILLACLARA SAS | L2: 901250630 | M2: 45797 | N2: 11:30 a.m | O2: si | P2: 1 | Q2: 106.666 | R2: PLANEAR | S2: 1.0.6 Diagnóstico del Sistema de Gestión de Seguridad y Salud en el Trabajo (SG-SST) 0312 DE 2019 | T2: 2 | U2: No firmo firma de termminos y condiciones por temas de no tener contraseña y usuario,se le presenta el programa .se le realiza evaluacion inicial | V2: 45807 | W2: 10 | X2: 14 | Y2: ACTIVO
A3: 45751 | C3: VIERNES | D3: TU EMPRESA SEGURA | E3: Juan Diego | F3: MERCEDES CARVAJAL OSPINA | G3: Cédula de Ciudadanía | H3: 21481666 | I3: mercedesemprendedora2023@gmail.com | J3: 3053436587 | K3: ALMA BOTANICA SAS | L3: 901817841 | M3: 45751 | N3: 11:30a.m | O3: si | P3: 4 | Q3: 213000 | R3: PLANEAR | S3: 1.0.4 Acompañamiiento/Asesoría sobre SGSST | T3: 2 | U3: el dia martes 1 de abril se llamo a la empresa para poder validar si se peude contactar ya que s ehabia intentado anteriormente y no se habia logrado Presentación del Programa: Registro Usuario y contraseña, términos y condiciones y se explica reporte de incidentes y accidentes ante la ARL | V3: 45807 | W3: 56 | X3: 2 | Y3: ACTIVO
A4: 45744 | C4: VIERNES | D4: TU EMPRESA SEGURA | E4: Cristhian | F4: Ana Maria Campuzano Arboleda | G4: Cédula de Ciudadanía | H4: 1007445947 | I4: anam_campuzano@hotmail.com | J4: 3217213077 | K4: ANA CAMPUZANO ARBOLEDA | L4: 1007445947 | M4: 45744 | N4: 11:30a.m | O4: si | P4: 2 | Q4: 106.666 | R4: PLANEAR | S4: 1.0.0 Bienvenida | T4: 1 | U4: Bienvenida al programa, se le explica detalladamente en que consiste y la duración estimada, se Indica cómo firmar los términos y condiciones, se agenda la reunión periódica, semanal, los viernes de 11:30 a 12:15pm | V4: 45807 | W4: 63 | X4: 2 | Y4: ACTIVO
A5: 45751 | C5: VIERNES | D5: TU EMPRESA SEGURA | E5: Juan Diego | F5: MELISSA MARIA ROMAN BURITICA | G5: Cédula de Ciudadanía | H5: 1040039119 | I5: gestionhumana@blackriverflowers.com | J5: 3173882936 | K5: BLACKRIVER FLOWERS SAS C I | L5: 900841005 | M5: 45751 | N5: 10:40a. m. | O5: si | P5: 3 | Q5: 106.666 | R5: PLANEAR | S5: 1.0.1 Firma de Términos y Condiciones | T5: 1 | U5: el dia viernes 21 de marzo se llamo a la empresa para validar la llegada del correo electronico con el usuario y la contraseña a lo cual indicaron que si les llego y que no han tenido ningun inconveniente | V5: 45807 | W5: 56 | X5: 55 | Y5: ACTIVO
A6: 45751 | C6: VIERNES | D6: TU EMPRESA SEGURA | E6: Juan Diego | F6: CLAUDIA PATRICIA MOLINA SANTOS | G6: Cédula de Ciudadanía | H6: 1070989191 | I6: clau300625@hotmail.es | J6: 3132973915 | K6: BORJA FLOWERS SAS | L6: 901546567 | M6: 45751 | N6: 3:55p. m. | O6: si | P6: 3 | Q6: 106.666 | R6: PLANEAR | S6: 1.0.0 Bienvenida | T6: 1 | U6: el dia viernes 21 de marzo se llamo a la empresa para validar la llegada del correo electronico con el usuario y la contraseña a lo cual indicaron que si les llego y que no han tenido ningun inconveniente | V6: 45807 | W6: 56 | X6: 30 | Y6: ACTIVO
A7: 45717 | C7: JUEVES | D7: TU EMPRESA SEGURA | E7: LUZ | F7: JUBER NEVARDO MARTINEZ GIRALDO | G7: Cédula de Ciudadanía | H7: 1039685226 | I7: adm.car.mc@gmail.com | J7: 3206709930 | K7: CARNES MONTECARLO | L7: 43476587 | M7: 45792 | N7: 1:15 p.m | O7: no | P7: 3 | Q7: 106.666 | R7: PLANEAR | S7: 1.0.2 Socialización SGSST | T7: 2 | U7: Solicita reprogramar reunion para otro dia,teniendo en cuenta que la agenda esta copada ,se le enviara por correo tareas para la proxima conexion. | V7: 45807 | W7: 90 | X7: 4 | Y7: ACTIVO
A8: 45751 | C8: VIERNES | D8: TU EMPRESA SEGURA | E8: Juan Diego | F8: MONICA YANETH OCAMPO SERNA | G8: Cédula de Ciudadanía | H8: 1036780830 | I8: floresmundocolores@gmail.com | J8: 3147830285 | K8: CI FLORES MUNDO COLORES SAS | L8: 900509996 | M8: 45751 | N8: 3:05PM | O8: si | P8: 3 | Q8: 106.666 | R8: PLANEAR | S8: 1.0.0 Bienvenida | T8: 1 | U8: el dia viernes 21 de marzo se llamo a la empresa para validar la llegada del correo electronico con el usuario y la contraseña a lo cual indicaron que si les llego y que no han tenido ningun inconveniente | V8: 45807 | W8: 56 | X8: 3 | Y8: ACTIVO
A9: 45751 | C9: VIERNES | D9: TU EMPRESA SEGURA | E9: Cristhian | F9: Jorge ignacio Martínez García | G9: Cédula de Ciudadanía | H9: 70952794 | I9: j73jimg@hotmail.com | J9: 3216422617 | K9: EMTURPE LIMITADA | L9: 900112921 | M9: 45751 | N9: 7:15a. m. | O9: si | P9: 4 | Q9: 213000 | R9: PLANEAR | S9: 1.0.0 Bienvenida | T9: 1 | U9: se realiza la reunion de bienvenida pero en la mitad de la reunion se tuvieron problemas de connexion por lo cual se finaliza la misma | V9: 45807 | W9: 56 | X9: 5 | Y9: ACTIVO
A10: 45797 | C10: MARTES | D10: TU EMPRESA SEGURA | E10: LUZ | J10: 3104997696 | K10: ESTRUCTURAS METALICAS DEL CHOCO | M10: 45797 | N10: 10:40 a.m | O10: si | P10: 3 | Q10: 106.666 | R10: PLANEAR | S10: 1.0.0 Bienvenida | T10: 1 | U10: Bienvenida al programa, No firmo firma de termminos y condiciones por temas de no tener contraseña y usuario,se le presenta el programa .se le realiza evaluacion inicial | V10: 45807 | W10: 10 | X10: 4 | Y10: ACTIVO
A11: 45797 | C11: MARTES | D11: TU EMPRESA SEGURA | E11: LUZ | F11: Kerly Andrea Ortiz Ramirez | G11: Cédula de Ciudadanía | H11: 1128395305 | I11: Kerlyandreaortiz1407@gmail.com | J11: 3128926799 | K11: FOTO SCANNER | L11: 1128395305 | M11: 45797 | N11: 1:00 p.m | O11: si | P11: 1 | Q11: 106.666 | R11: PLANEAR | S11: 1.0.0 Bienvenida | T11: 1 | U11: Se realiza bienvenida, no firmo firma de termminos y condiciones por temas de no tener contraseña y usuario,se le presenta el programa . | V11: 45807 | W11: 10 | X11: 3 | Y11: ACTIVO
A12: 45775 | C12: VIERNES | D12: TU EMPRESA SEGURA | E12: Cristhian | F12: LUISA GARCIA | G12: Cédula de Ciudadanía | H12: 1036929374 | I12: luisayepes02@gmail.com | J12: 3194892497 | K12: HYDRANFLOWERS S.A.S | L12: 901166099 | M12: 46133 | N12: 11:00a. m. | O12: si | P12: 2 | Q12: 106.666 | R12: PLANEAR | S12: 1.0.0 Bienvenida | T12: 1 | U12: Bienvenida al programa, se le explica detalladamente en que consiste y la duración estimada, se Indica cómo firmar los términos y condiciones, se agenda la reunión periódica, semanal, los viernes de 3:00 a 3:45pm, se actualiza el correo de contacto: claoarbo@hotmail.com | V12: 45807 | W12: 32 | X12: 7 | Y12: ACTIVO
A13: 45741 | C13: MARTES | D13: TU EMPRESA SEGURA | E13: LUZ | F13: LIANA OCAMPO | G13: Cédula de Ciudadanía | H13: 1036778480 | I13: Locampo@picados.com.co | J13: 3127198417 | K13: INVERSIONES VALLEJUELO S.A.S. | L13: 900655932 | M13: 45741 | N13: 11:00 AM - 12:00 PM | O13: si | P13: 3 | Q13: 106.666 | R13: PLANEAR | S13: 1.0.0 Bienvenida | T13: 1 | U13: el dia viernes 21 de marzo se llamo a la empresa para validar la llegada del correo electronico con el usuario y la contraseña a lo cual indicaron que si les llego y que no han tenido ningun inconveniente | V13: 45807 | W13: 66 | X13: 42 | Y13: ACTIVO
A14: 45811 | E14: LUZ | F14: Jorge Eliecer Gómez Garcia | G14: Cédula de Ciudadanía | H14: 1128403927 | I14: gerenciacakareos@gmail.com | J14: 3148312199 | K14: JORGE ELIECER GOMEZ | L14: 1128403927 | M14: 45811 | N14: 0.62847222 | O14: si | P14: 1 | Q14: 106.666 | R14: PLANEAR | S14: 0. No conexión | T14: 0 | U14: Esta en duda si continua con tu empresa segura comfama o sigue con las niñas que le llevan el sistema en el momento. | V14: 45807 | W14: 4 | X14: 5 | Y14: ACTIVO
A15: 45741 | C15: MARTES | D15: TU EMPRESA SEGURA | E15: JUAN DIEGO | F15: LADY NATALIA RODRÍGUEZ OSPINA | G15: Cédula de Ciudadanía | H15: 1036937209 | I15: Natalia.rodriguez7209@gmail.com | J15: 3128650034 | K15: JULIAN GALLEGO CASTRO | L15: 15448886 | M15: 45741 | N15: 1:00p.m. | O15: si | P15: 1 | Q15: 106.666 | R15: PLANEAR | S15: 1.0.0 Bienvenida | T15: 1 | U15: el dia viernes 21 de marzo se llamo a la empresa para validar la llegada del correo electronico con el usuario y la contraseña a lo cual indicaron que si les llego y que no han tenido ningun inconveniente. Primer conexión explicación del proyecto | V15: 45807 | W15: 66 | X15: 11 | Y15: ACTIVO
A16: 45744 | C16: VIERNES | D16: TU EMPRESA SEGURA | E16: Cristhian | F16: Dora Luz Arbelaez | G16: Cédula de Ciudadanía | H16: 39382394 | I16: doraluzarbelaez@gmail.com | J16: 3113247283 | K16: LACTEOS BUENA VISTA SABORES NATURALES S A | L16: 900167311 | M16: 46133 | N16: 1:40PM | O16: si | P16: 3 | Q16: 106.666 | R16: PLANEAR | S16: 1.0.0 Bienvenida | T16: 1 | U16: Bienvenida al programa, se le explica detalladamente en que consiste y la duración estimada, se Indica cómo firmar los términos y condiciones, se agenda la reunión periódica, semanal, los viernes de 1:30 a 2:15Pm | V16: 45807 | W16: 63 | X16: 11 | Y16: ACTIVO
A17: 45737 | C17: VIERNES | D17: TU EMPRESA SEGURA | E17: Cristhian | F17: JUAN FELIPE LÓPEZ OROZCO | G17: Cédula de Ciudadanía | H17: 15356506 | I17: felipelopezorozco2020@gmail.com ,lopetransvolq@gmail.com | J17: 3136468404 | K17: LOPETRANS SAS | L17: 901636833 | M17: 45737 | N17: 7:00AM | O17: si | P17: 1 | Q17: 106.666 | R17: PLANEAR | S17: 1.0.0 Bienvenida | T17: 1 | U17: Bienvenida al programa, se le explica detalladamente en que consiste y la duración estimada, se Indica cómo firmar los términos y condiciones, se agenda la reunión periódica, semanal, los Lunes de 7:15 a 8:00am | V17: 45807 | W17: 70 | X17: 5 | Y17: ACTIVO
A18: 45735 | C18: MERCOLES | D18: TU EMPRESA SEGURA | E18: CRISTIAN | F18: BRANDON YESID VELASQUEZ LOPEZ | G18: Cédula de Ciudadanía | H18: 1013654370 | I18: Maderas.sanrafael@hotmail.com | J18: 3105299313 | K18: MADERAS SAN RAFAEL | L18: 1013654370 | M18: 45735 | N18: 02:00p. m. | O18: si | P18: 4 | Q18: 213000 | R18: PLANEAR | S18: 1.0.0 Bienvenida | T18: 1 | U18: Bienvenida al programa, se le explica detalladamente en que consiste y la duración estimada, se Indica cómo firmar los términos y condiciones, se agenda la reunión periódica, semanal | V18: 45807 | W18: 72 | X18: 4 | Y18: ACTIVO
A19: 45717 | C19: JUEVES | D19: TU EMPRESA SEGURA | E19: LUZ | F19: OLGA LUCIA LOPEZ ALVAREZ | G19: Cédula de Ciudadanía | H19: 43862379 | I19: Asesorias@encontac.com | J19: 3147571005 | K19: OLGA LÓPEZ | L19: 43862379 | M19: 45785 | O19: si | P19: 1 | Q19: 106.666 | R19: PLANEAR | S19: 1.1.1. Responsable del Sistema de Gestión de Seguridad y Salud en el Trabajo SG-SST | T19: 0,5 | U19: se realiza digitacion y explicacion de archivo,se le explica el perfilsociodemografica y queda como tarea,se revisa afiliaciones y documento de responsable del sistema. | V19: 45807 | W19: 90 | X19: 2 | Y19: ACTIVO
A20: 45751 | C20: VIERNES | D20: TU EMPRESA SEGURA | E20: Juan Diego | F20: CARLOS ALBERTO BEJARANO CAMACHO | G20: Cédula de Ciudadanía | H20: 79291337 | I20: carlos.bejarano@prosolar.com.co | J20: 3104387811 | K20: PROSOLAR S.A.S | L20: 901039724 | M20: 45751 | N20: 9:00a. m. | O20: si | P20: 2 | Q20: 106.666 | R20: PLANEAR | S20: 1.0.0 Bienvenida | T20: 1 | U20: el dia viernes 21 de marzo se llamo a la empresa para validar la llegada del correo electronico con el usuario y la contraseña a lo cual indicaron que si les llego y que no han tenido ningun inconveniente | V20: 45807 | W20: 56 | X20: 6 | Y20: ACTIVO
A21: 45733 | C21: LUNES | D21: TU EMPRESA SEGURA | E21: Cristhian | F21: SAUL GÓMEZ JARAMILLO | G21: Cédula de Ciudadanía | H21: 15384344 | I21: saul.gomez@hotmai.es | J21: 3148500297 | K21: SAÚL GÓMEZ | L21: 15384344 | M21: 45733 | N21: 02:00p. m. | O21: si | P21: 2 | Q21: 106.666 | R21: PLANEAR | S21: 1.0.0 Bienvenida | T21: 1 | V21: 45807 | W21: 74 | X21: 8 | Y21: ACTIVO
A22: 45724 | C22: JUEVES | D22: TU EMPRESA SEGURA | E22: LUZ | F22: MANDIRELIS FLOREZ MARIN | G22: Cédula de Ciudadanía | H22: 39453906 | I22: mandy.f.m@hotmail.com | J22: 3128523870 | K22: SUMINISTRO Y TRANSPORTE DE MATERIAL RIOS Y FLOREZ SAS | L22: 901590411 | M22: 45776 | N22: 9:00a, m. | O22: si | P22: 2 | Q22: 106.666 | R22: PLANEAR | S22: 1.0.1 Firma de Términos y Condiciones | T22: 1 | U22: Se actualiza perfilsociodemografico,firma de terminos y condiciones,presentacion del programa. | V22: 45807 | W22: 83 | X22: 23 | Y22: ACTIVO
A23: 45731 | C23: JUEVES | D23: TU EMPRESA SEGURA | E23: LUZ | F23: JAVIER IGNACIO GARCIA GARCIA | G23: Cédula de Ciudadanía | H23: 15380272 | I23: teccons@hotmail.com | J23: 3113177651 | K23: TECCONS S.A.S | L23: 900709843 | M23: 45792 | N23: 3:55p. m. | O23: si | P23: 5 | Q23: 213000 | R23: PLANEAR | S23: 1.1.4 Afiliación al Sistema General de Riesgos Laborales | T23: 0,5 | U23: Se realiza el perfilsociodemografico,se le enviara correo de verificacion para montar el numeral 1.1.4. | V23: 45807 | W23: 76 | X23: 2 | Y23: ACTIVO
A24: 45717 | C24: JUEVES | D24: TU EMPRESA SEGURA | E24: LUZ | F24: YURANI ANDREA MADRID MORALES | G24: Cédula de Ciudadanía | H24: 1039681747 | I24: Yurandra198720@gmail.com | J24: 3136884875 | K24: TROPICAL1987 | L24: 1039681747 | M24: 45785 | N24: 7:15 a.m | O24: si | P24: 3 | Q24: 106.666 | R24: PLANEAR | S24: 1.1.1. Responsable del Sistema de Gestión de Seguridad y Salud en el Trabajo SG-SST | T24: 0,5 | U24: Se diligencia responsabilidades,se adelanta tema de archivo documental,se envia correo de como montar evidencia de afiliacion,como realizar el perfilsociodemografico. | V24: 45807 | W24: 90 | X24: 4 | Y24: ACTIVO
A25: 45742 | C25: MIERCOLES | D25: TU EMPRESA SEGURA | E25: Cristhian | F25: SANDRA MILENA ARANGO JARAMILLO | G25: Cédula de Ciudadanía | H25: 39189386 | I25: sandra.arango@urantus.com | J25: 3022152280 | K25: URANTUS GREENHOUSES S.A.S | L25: 901268585 | M25: 45742 | N25: 9:00AM | O25: si | P25: 5 | Q25: 213000 | R25: PLANEAR | S25: 1.0.0 Bienvenida | T25: 1 | U25: Bienvenida al programa, se le explica detalladamente en que consiste y la duración estimada, se Indica cómo firmar los términos y condiciones, se agenda la reunión periódica, semanal, los viernes de 10:40 a 11:25Am | V25: 45807 | W25: 65 | X25: 9 | Y25: ACTIVO
A26: 45751 | C26: VIERNES | D26: TU EMPRESA SEGURA | E26: Cristhian | F26: VANESSA VARGAS ALZATE | G26: Cédula de Ciudadanía | H26: 1037649854 | I26: avelicafe@gmail.com | J26: 3114323737 | K26: VANESSA VARGAS ALZATE | L26: 1037649854 | M26: 45751 | N26: 8:05a. m. | O26: si | P26: 2 | Q26: 106.666 | R26: PLANEAR | S26: 1.0.0 Bienvenida | T26: 1 | U26: el dia viernes 21 de marzo se llamo a la empresa para validar la llegada del correo electronico con el usuario y la contraseña a lo cual indicaron que si les llego y que no han tenido ningun inconveniente | V26: 45807 | W26: 56 | X26: 2 | Y26: ACTIVO

Sheet PHVA
A1: Ciclo PHVA | B1: ÍTEM ESTÁNDAR | C1: PORCENTAJE DE AVANCE | D1: MESES DE ACOMPAÑAMIENTO | E1: %POR MES | F1: ACTIVIDADES PLANEADAS | G1: ACTIVIDADES EJECUTADAS | H1: INDICADORES
A2: PLANEAR | B2: 1.0.0 Bienvenida | C2: 1 | D2: MES 1 | E2: =SUM(C2+C6+C7+C11+C10) -> 9 | F2: 5 | H2: =(F2*G2)/100 -> 0
A3: PLANEAR | B3: 0. No conexión | C3: 0 | D3: MES 1
A4: PLANEAR | B4: 0. No conexión Savanna | C4: 0 | D4: MES 1
A5: PLANEAR | B5: 0.1 Trabajo autónomo analista en plataforma | C5: 0.5 | D5: MES 1
A6: PLANEAR | B6: 1.0.1 Firma de Términos y Condiciones | C6: 1 | D6: MES 1
A7: PLANEAR | B7: 1.0.2 Socialización SGSST | C7: 2 | D7: MES 1
A8: PLANEAR | B8: 1.0.3 Navegando en la plataforma y beneficios del programa | C8: 1 | D8: MES 1
A9: PLANEAR | B9: 1.0.4 Acompañamiiento/Asesoría sobre SGSST | C9: 2 | D9: MES 1
A10: PLANEAR | B10: 1.0.5 Diagnóstico de Madurez | C10: 3 | D10: MES 1
A11: PLANEAR | B11: 1.0.6 Diagnóstico del Sistema de Gestión de Seguridad y Salud en el Trabajo (SG-SST) 0312 DE 2019 | C11: 2 | D11: MES 1 | F11: 5
A12: PLANEAR | B12: 1.0.8 Acompañamiento AT/EL | C12: 3 | D12: MES 2 | E12: =SUM(C12+C14+C15+C16) -> 8
A13: PLANEAR | B13: 1.0.8 Savanna Campañas de Sencibilización | C13: 4 | D13: MES 2
A14: PLANEAR | B14: 1.0.9 Savanna Ruta de Bienestar | C14: 4 | D14: MES 2
A15: PLANEAR | B15: 1.1.1. Responsable del Sistema de Gestión de Seguridad y Salud en el Trabajo SG-SST | C15: 0.5 | D15: MES 2
A16: PLANEAR | B16: 1.1.2 Responsabilidades en el Sistema de Gestión de Seguridad y Salud en el Trabajo – SG-SST | C16: 0.5 | D16: MES 2
A17: PLANEAR | B17: 1.1.3 Asignación de recursos para el Sistema de Gestión en Seguridad y Salud en el Trabajo – SG-SST | C17: 0.5 | D17: MES 3 | E17: =SUM(C17:C20) -> 2 | F17: 4
A18: PLANEAR | B18: 1.1.4 Afiliación al Sistema General de Riesgos Laborales | C18: 0.5 | D18: MES 3
A19: PLANEAR | B19: 1.1.5 Identificacion de trabajadores de alto riesgo y cotizacion de pension especial | C19: 0.5 | D19: MES 3
A20: PLANEAR | B20: 1.1.6 Conformación COPASST | C20: 0.5 | D20: MES 3
A21: PLANEAR | B21: 1.1.7 Capacitación COPASST | C21: 0.5 | D21: MES 4 | E21: =SUM(C21:C24) -> 5 | F21: 4
A22: PLANEAR | B22: 1.1.8 Conformación Comité de Convivencia | C22: 0.5 | D22: MES 4
A23: PLANEAR | B23: 1.2.1 Programa Capacitación promoción y prevención PYP | C23: 2 | D23: MES 4
A24: PLANEAR | B24: 1.2.2 Inducción y Reinducción en Sistema de Gestión de Seguridad y Salud en el Trabajo SG-SST, actividades de Promoción y Prevención PyP | C24: 2 | D24: MES 4
A25: PLANEAR | B25: 1.2.3 Responsables del Sistema de Gestión de Seguridad y Salud en el Trabajo SG-SST con curso virtual de 50 horas | C25: 2 | D25: MES 5 | E25: =SUM(C25:C28) -> 5 | F25: 4
A26: PLANEAR | B26: 2.1.1 Política del Sistema de Gestión de Seguridad y Salud en el Trabajo SG-SST firmada, fechada y comunicada al COPASST | C26: 1 | D26: MES 5
A27: PLANEAR | B27: 2.2.1 Objetivos definidos, claros, medibles, cuantificables, con metas, documentados, revisados del SG-SST | C27: 1 | D27: MES 5
A28: PLANEAR | B28: 2.3.1 Evaluación e identificación de prioridades | C28: 1 | D28: MES 5
A29: PLANEAR | B29: 2.4.1 Plan que identifica objetivos, metas, responsabilidad, recursos con cronograma y firmado | C29: 2 | D29: MES 6 | E29: =SUM(C29:C32) -> 7 | F29: 4
A30: PLANEAR | B30: 2.5.1 Archivo o retención documental del Sistema de Gestión en Seguridad y Salud en el Trabajo SG-SST | C30: 2 | D30: MES 6
A31: PLANEAR | B31: 2.6.1 Rendición sobre el desempeño | C31: 1 | D31: MES 6
A32: PLANEAR | B32: 2.7.1 Matriz legal | C32: 2 | D32: MES 6
A33: PLANEAR | B33: 2.8.1 Mecanismos de comunicación, auto reporte en Sistema de Gestión de Seguridad y Salud en el Trabajo SG-SST | C33: 1 | D33: MES 7 | E33: =SUM(C33:C36) -> 5 | F33: 4
A34: PLANEAR | B34: 2.9.1 Identificación, evaluación, para adquisición de productos y servicios en Sistema de Gestión de Seguridad y Salud en el Trabajo SG-SST | C34: 1 | D34: MES 7
A35: PLANEAR | B35: 2.10.1 Evaluación y selección de proveedores y contratistas | C35: 2 | D35: MES 7
A36: HACER | B36: 2.11.1 Evaluación del impacto de cambios internos y externos en el Sistema de Gestión de Seguridad y Salud en el Trabajo SG-SST | C36: 1 | D36: MES 7
A37: HACER | B37: 3.1.1 Descripcion sociodemografica.Diagnostico de Condiciones de Salud | C37: 1 | D37: MES 8 | E37: =SUM(C37:C41) -> 5 | F37: 5
A38: HACER | B38: 3.1.2 Actividades de Promoción y Prevención en Salud | C38: 1 | D38: MES 8
A39: HACER | B39: 3.1.3 Información al médico de los perfiles de cargo | C39: 1 | D39: MES 8
A40: HACER | B40: 3.1.4 Realización de los evaluaciones médicas ocupacionales: Peligros- Periodicidad Comunicación al Trabajador | C40: 1 | D40: MES 8
...

Sheet VERO EMPRESAS ACTIVAS
A1: FECHA INICIO DEL PROGRAMA | B1: NOMBRE DE LA EMPRESA | C1: NIT | D1: MES DE INICIO COBERTURA | E1: MESES A CORTE 30 DE MAYO | F1: ACTIVO/INACTIVO | G1: % RESOLUCIÓN 0312 de 2019 | H1: ACCIONES PLANEADAS | I1: % AVANCE | J1: ESTADO INICIAL | K1: FECHA CORTE DE INFORME | L1: VALOR PROGRAMA | M1: AVANCE EN PRODUCTIVIDAD | N1: VALOR A FACTURAR | O1: DÍAS EN EL PROGRAMA | P1: ACIONES EJECUTADAS
A2: 45717 | B2: CARNES MONTECARLO | C2: 43476587 | D2: MARZO | E2: 3 | F2: ACTIVO | G2: 51.08 | H2: 14 | I2: 5 | J2: =IF(G2<=60,"CRÍTICO",IF(G2<=85,"MODERADO","ACEPTABLE")) -> CRÍTICO | K2: 45807 | L2: =VLOOKUP(C2,'CRM ANALISTAS'!$M$2:$Q$206,5,0) -> 106666 | M2: =VLOOKUP(B2,GRÁFICAS!$A$4:$C$28,3,0) -> 5 | N2: =L2*E2 -> 319998 | O2: 90 | P2: =(H2*I2)/100 -> 0.7
A3: 45717 | B3: OLGA LÓPEZ | C3: 43862379 | D3: MARZO | E3: 3 | F3: ACTIVO | G3: 56.83 | H3: 14 | I3: 3.5 | J3: =IF(G3<=60,"CRÍTICO",IF(G3<=85,"MODERADO","ACEPTABLE")) -> CRÍTICO | K3: 45807 | L3: =VLOOKUP(C3,'CRM ANALISTAS'!$M$2:$Q$206,5,0) -> 106666 | M3: =VLOOKUP(B3,GRÁFICAS!$A$4:$C$28,3,0) -> 3.5 | N3: =L3*E3 -> 319998 | O3: 90 | P3: =(H3*I3)/100 -> 0.49
A4: 45717 | B4: TROPICAL1987 | C4: 1039681747 | D4: MARZO | E4: 3 | F4: ACTIVO | G4: 34.08 | H4: 14 | I4: 8 | J4: =IF(G4<=60,"CRÍTICO",IF(G4<=85,"MODERADO","ACEPTABLE")) -> CRÍTICO | K4: 45807 | L4: =VLOOKUP(C4,'CRM ANALISTAS'!$M$2:$Q$206,5,0) -> 106666 | M4: =VLOOKUP(B4,GRÁFICAS!$A$4:$C$28,3,0) -> 8 | N4: =L4*E4 -> 319998 | O4: 90 | P4: =(H4*I4)/100 -> 1.12
A5: 45724 | B5: SUMINISTRO Y TRANSPORTE DE MATERIAL RIOS Y FLOREZ SAS | C5: 901590411 | D5: MARZO | E5: 3 | F5: ACTIVO | G5: 0 | H5: 14 | I5: 6 | J5: =IF(G5<=60,"CRÍTICO",IF(G5<=85,"MODERADO","ACEPTABLE")) -> CRÍTICO | K5: 45807 | L5: =VLOOKUP(C5,'CRM ANALISTAS'!$M$2:$Q$206,5,0) -> 106666 | M5: =VLOOKUP(B5,GRÁFICAS!$A$4:$C$28,3,0) -> 6 | N5: =L5*E5 -> 319998 | O5: 83 | P5: =(H5*I5)/100 -> 0.84
A6: 45731 | B6: TECCONS S.A.S | C6: 900709843 | D6: MARZO | E6: 3 | F6: ACTIVO | G6: 48.58 | H6: 14 | I6: 13 | J6: =IF(G6<=60,"CRÍTICO",IF(G6<=85,"MODERADO","ACEPTABLE")) -> CRÍTICO | K6: 45807 | L6: =VLOOKUP(C6,'CRM ANALISTAS'!$M$2:$Q$206,5,0) -> 213000 | M6: =VLOOKUP(B6,GRÁFICAS!$A$4:$C$28,3,0) -> 13 | N6: =L6*E6 -> 639000 | O6: 76 | P6: =(H6*I6)/100 -> 1.82
A7: 45733 | B7: SAÚL GÓMEZ | C7: 15384344 | D7: MARZO | E7: 3 | F7: ACTIVO | G7: 85.58 | H7: 14 | I7: 13 | J7: =IF(G7<=60,"CRÍTICO",IF(G7<=85,"MODERADO","ACEPTABLE")) -> ACEPTABLE | K7: 45807 | L7: =VLOOKUP(C7,'CRM ANALISTAS'!$M$2:$Q$206,5,0) -> 106666 | M7: =VLOOKUP(B7,GRÁFICAS!$A$4:$C$28,3,0) -> 13 | N7: =L7*E7 -> 319998 | O7: 74 | P7: =(H7*I7)/100 -> 1.82
A8: 45735 | B8: MADERAS SAN RAFAEL | C8: 1013654370 | D8: MARZO | E8: 3 | F8: ACTIVO | G8: 0 | H8: 14 | I8: 15 | J8: =IF(G8<=60,"CRÍTICO",IF(G8<=85,"MODERADO","ACEPTABLE")) -> CRÍTICO | K8: 45807 | L8: =VLOOKUP(C8,'CRM ANALISTAS'!$M$2:$Q$206,5,0) -> 213000 | M8: =VLOOKUP(B8,GRÁFICAS!$A$4:$C$28,3,0) -> 15 | N8: =L8*E8 -> 639000 | O8: 72 | P8: =(H8*I8)/100 -> 2.1
A9: 45737 | B9: LOPETRANS SAS | C9: 901636833 | D9: MARZO | E9: 3 | F9: ACTIVO | G9: 50.58 | H9: 14 | I9: 23 | J9: =IF(G9<=60,"CRÍTICO",IF(G9<=85,"MODERADO","ACEPTABLE")) -> CRÍTICO | K9: 45807 | L9: =VLOOKUP(C9,'CRM ANALISTAS'!$M$2:$Q$206,5,0) -> 106666 | M9: =VLOOKUP(B9,GRÁFICAS!$A$4:$C$28,3,0) -> 23 | N9: =L9*E9 -> 319998 | O9: 70 | P9: =(H9*I9)/100 -> 3.22
A10: 45741 | B10: INVERSIONES VALLEJUELO S.A.S. | C10: 900655932 | D10: MARZO | E10: 3 | F10: ACTIVO | G10: 91.58 | H10: 14 | I10: 11 | J10: =IF(G10<=60,"CRÍTICO",IF(G10<=85,"MODERADO","ACEPTABLE")) -> ACEPTABLE | K10: 45807 | L10: =VLOOKUP(C10,'CRM ANALISTAS'!$M$2:$Q$206,5,0) -> 106666 | M10: =VLOOKUP(B10,GRÁFICAS!$A$4:$C$28,3,0) -> 11 | N10: =L10*E10 -> 319998 | O10: 66 | P10: =(H10*I10)/100 -> 1.54
A11: 45741 | B11: JULIAN GALLEGO CASTRO | C11: 15448886 | D11: MARZO | E11: 3 | F11: ACTIVO | G11: 6 | H11: 14 | I11: 15 | J11: =IF(G11<=60,"CRÍTICO",IF(G11<=85,"MODERADO","ACEPTABLE")) -> CRÍTICO | K11: 45807 | L11: =VLOOKUP(C11,'CRM ANALISTAS'!$M$2:$Q$206,5,0) -> 106666 | M11: =VLOOKUP(B11,GRÁFICAS!$A$4:$C$28,3,0) -> 15 | N11: =L11*E11 -> 319998 | O11: 66 | P11: =(H11*I11)/100 -> 2.1
A12: 45742 | B12: JOSE ARENAS ORTEGA | C12: 91292432 | D12: MARZO | E12: 1 | F12: INACTIVO | G12: 0 | H12: 0 | I12: 0 | J12: =IF(G12<=60,"CRÍTICO",IF(G12<=85,"MODERADO","ACEPTABLE")) -> CRÍTICO | K12: 45807 | L12: 0 | M12: 0 | N12: =L12*E12 -> 0 | O12: 0 | P12: =(H12*I12)/100 -> 0
A13: 45742 | B13: URANTUS GREENHOUSES S.A.S | C13: 901268585 | D13: MARZO | E13: 3 | F13: ACTIVO | G13: 91.58 | H13: 14 | I13: 18.5 | J13: =IF(G13<=60,"CRÍTICO",IF(G13<=85,"MODERADO","ACEPTABLE")) -> ACEPTABLE | K13: 45807 | L13: =VLOOKUP(C13,'CRM ANALISTAS'!$M$2:$Q$206,5,0) -> 213000 | M13: =VLOOKUP(B13,GRÁFICAS!$A$4:$C$28,3,0) -> 18.5 | N13: =L13*E13 -> 639000 | O13: 65 | P13: =(H13*I13)/100 -> 2.59
A14: 45744 | B14: ANA CAMPUZANO ARBOLEDA | C14: 1007445947 | D14: MARZO | E14: 3 | F14: ACTIVO | G14: 0 | H14: 14 | I14: 17.5 | J14: =IF(G14<=60,"CRÍTICO",IF(G14<=85,"MODERADO","ACEPTABLE")) -> CRÍTICO | K14: 45807 | L14: =VLOOKUP(C14,'CRM ANALISTAS'!$M$2:$Q$206,5,0) -> 106666 | M14: =VLOOKUP(B14,GRÁFICAS!$A$4:$C$28,3,0) -> 17.5 | N14: =L14*E14 -> 319998 | O14: 63 | P14: =(H14*I14)/100 -> 2.45
A15: 45744 | B15: LACTEOS BUENA VISTA SABORES NATURALES S A | C15: 900167311 | D15: MARZO | E15: 3 | F15: ACTIVO | G15: 0 | H15: 14 | I15: 18 | J15: =IF(G15<=60,"CRÍTICO",IF(G15<=85,"MODERADO","ACEPTABLE")) -> CRÍTICO | K15: 45807 | L15: =VLOOKUP(C15,'CRM ANALISTAS'!$M$2:$Q$206,5,0) -> 106666 | M15: =VLOOKUP(B15,GRÁFICAS!$A$4:$C$28,3,0) -> 18 | N15: =L15*E15 -> 319998 | O15: 63 | P15: =(H15*I15)/100 -> 2.52
A16: 45751 | B16: ALMA BOTANICA SAS | C16: 901817841 | D16: ABRIL | E16: 2 | F16: ACTIVO | G16: 0 | H16: 10 | I16: 10 | J16: =IF(G16<=60,"CRÍTICO",IF(G16<=85,"MODERADO","ACEPTABLE")) -> CRÍTICO | K16: 45807 | L16: =VLOOKUP(C16,'CRM ANALISTAS'!$M$2:$Q$206,5,0) -> 213000 | M16: =VLOOKUP(B16,GRÁFICAS!$A$4:$C$28,3,0) -> 10 | N16: =L16*E16 -> 426000 | O16: 56
A17: 45751 | B17: BLACKRIVER FLOWERS SAS C I | C17: 900841005 | D17: ABRIL | E17: 2 | F17: ACTIVO | G17: 99.08 | H17: 10 | I17: 14.5 | J17: =IF(G17<=60,"CRÍTICO",IF(G17<=85,"MODERADO","ACEPTABLE")) -> ACEPTABLE | K17: 45807 | L17: =VLOOKUP(C17,'CRM ANALISTAS'!$M$2:$Q$206,5,0) -> 106666 | M17: =VLOOKUP(B17,GRÁFICAS!$A$4:$C$28,3,0) -> 14.5 | N17: =L17*E17 -> 213332 | O17: 56
A18: 45751 | B18: BORJA FLOWERS SAS | C18: 901546567 | D18: ABRIL | E18: 2 | F18: ACTIVO | G18: 0 | H18: 10 | I18: 5 | J18: =IF(G18<=60,"CRÍTICO",IF(G18<=85,"MODERADO","ACEPTABLE")) -> CRÍTICO | K18: 45807 | L18: =VLOOKUP(C18,'CRM ANALISTAS'!$M$2:$Q$206,5,0) -> 106666 | M18: =VLOOKUP(B18,GRÁFICAS!$A$4:$C$28,3,0) -> 5 | N18: =L18*E18 -> 213332 | O18: 56
A19: 45751 | B19: CI FLORES MUNDO COLORES SAS | C19: 900509996 | D19: ABRIL | E19: 2 | F19: ACTIVO | G19: 53.3 | H19: 10 | I19: 17.5 | J19: =IF(G19<=60,"CRÍTICO",IF(G19<=85,"MODERADO","ACEPTABLE")) -> CRÍTICO | K19: 45807 | L19: =VLOOKUP(C19,'CRM ANALISTAS'!$M$2:$Q$206,5,0) -> 106666 | M19: =VLOOKUP(B19,GRÁFICAS!$A$4:$C$28,3,0) -> 17.5 | N19: =L19*E19 -> 213332 | O19: 56
A20: 45751 | B20: EMTURPE LIMITADA | C20: 900112921 | D20: ABRIL | E20: 2 | F20: ACTIVO | G20: 0 | H20: 10 | I20: 11 | J20: =IF(G20<=60,"CRÍTICO",IF(G20<=85,"MODERADO","ACEPTABLE")) -> CRÍTICO | K20: 45807 | L20: =VLOOKUP(C20,'CRM ANALISTAS'!$M$2:$Q$206,5,0) -> 213000 | M20: =VLOOKUP(B20,GRÁFICAS!$A$4:$C$28,3,0) -> 11 | N20: =L20*E20 -> 426000 | O20: 56
